[141.533851624] 2022-03-22 20:32:50,477 - INFO - launcher: Starting sanity checks
[141.533851624] 2022-03-22 20:32:50,477 - INFO - launcher: Checking for Python 3.8+
[142.533779144] 2022-03-22 20:32:50,478 - INFO - launcher: Checking console encoding
[146.525382996] 2022-03-22 20:32:50,482 - INFO - launcher: Setting console encoding to UTF-8
[146.525382996] 2022-03-22 20:32:50,482 - INFO - launcher: Ensuring we're in the right environment
[148.515462875] 2022-03-22 20:32:50,484 - INFO - launcher: Adding local bins/ folder to path
[4730.909347534] 2022-03-22 20:32:55,066 - INFO - launcher: Required checks passed.
[4764.591693878] 2022-03-22 20:32:55,100 - INFO - launcher: Optional checks passed.
[4764.591693878] 2022-03-22 20:32:55,100 - INFO - launcher: Moving old musicbot log

######################### PRE-RUN SANITY CHECKS PASSED #########################

[10.8808383941650391] 2022-03-22 20:33:01,216 - WARNING - musicbot.config | In config.py::MainThread(19360), line 235 in run_checks: i18n file does not exist. Trying to fallback to config/i18n/en.json.
[10.8808383941650391] 2022-03-22 20:33:01,216 - INFO - musicbot.config | In config.py::MainThread(19360), line 250 in run_checks: Using i18n: config/i18n/en.json
[10.9477229118347168] 2022-03-22 20:33:01,283 - DEBUG - musicbot.bot | In bot.py::MainThread(19360), line 281 in _setup_logging: Set logging level to INFO
[10.9900817871093750] 2022-03-22 20:33:01,325 - DEBUG - musicbot.json | In json.py::MainThread(19360), line 9 in __init__: Init JSON obj with config/i18n/en.json
[11.7639923095703125] 2022-03-22 20:33:02,099 - INFO - musicbot.bot | In bot.py::MainThread(19360), line 105 in __init__: Starting MusicBot release-151221-1-g1df26df
[11.7639923095703125] 2022-03-22 20:33:02,099 - INFO - musicbot.bot | In bot.py::MainThread(19360), line 111 in __init__: Loaded autoplaylist with 2531 entries
[13.0639023780822754] 2022-03-22 20:33:03,399 - DEBUG - musicbot.spotify | In spotify.py::MainThread(19360), line 100 in get_token: Created a new access token: {'access_token': 'BQDq3v64WMJZ74VAZQ3CCKsYZw_8CTmNXqh98bQcG1BNwk83QpEa04Kk8IWhrtmicGWwaLwHJjXzsVuyx1w', 'token_type': 'Bearer', 'expires_in': 3600, 'expires_at': 1647966783}
[13.0639023780822754] 2022-03-22 20:33:03,399 - INFO - musicbot.bot | In bot.py::MainThread(19360), line 145 in __init__: Authenticated with Spotify successfully using client ID and secret.
[17.1128349304199219] 2022-03-22 20:33:07,448 - DEBUG - musicbot.bot | In bot.py::MainThread(19360), line 1119 in on_ready: Connection established, ready to go.
[17.1128349304199219] 2022-03-22 20:33:07,448 - DEBUG - musicbot.bot | In bot.py::MainThread(19360), line 430 in _cache_app_info: Caching app info
[17.4303448200225830] 2022-03-22 20:33:07,766 - DEBUG - musicbot.bot | In bot.py::MainThread(19360), line 924 in _scheck_ensure_env: Ensuring data folders exist
[17.4471249580383301] 2022-03-22 20:33:07,782 - DEBUG - musicbot.bot | In bot.py::MainThread(19360), line 939 in _scheck_server_permissions: Checking server permissions
[17.4471249580383301] 2022-03-22 20:33:07,782 - DEBUG - musicbot.bot | In bot.py::MainThread(19360), line 943 in _scheck_autoplaylist: Auditing autoplaylist
[17.4471249580383301] 2022-03-22 20:33:07,782 - DEBUG - musicbot.bot | In bot.py::MainThread(19360), line 947 in _scheck_configs: Validating config
[17.4471249580383301] 2022-03-22 20:33:07,782 - DEBUG - musicbot.config | In config.py::MainThread(19360), line 376 in async_validate: Validating options...
[17.4471249580383301] 2022-03-22 20:33:07,782 - DEBUG - musicbot.config | In config.py::MainThread(19360), line 388 in async_validate: Acquired owner id via API
[17.4471249580383301] 2022-03-22 20:33:07,782 - DEBUG - musicbot.bot | In bot.py::MainThread(19360), line 950 in _scheck_configs: Validating permissions config
[17.4471249580383301] 2022-03-22 20:33:07,782 - DEBUG - musicbot.permissions | In permissions.py::MainThread(19360), line 112 in async_validate: Validating permissions...
[17.4471249580383301] 2022-03-22 20:33:07,782 - DEBUG - musicbot.permissions | In permissions.py::MainThread(19360), line 116 in async_validate: Fixing automatic owner group
[17.4471249580383301] 2022-03-22 20:33:07,782 - INFO - musicbot.bot | In bot.py::MainThread(19360), line 1133 in on_ready: Connected: 883403929113731072/BaguzelMusicBot#2949
[17.4471249580383301] 2022-03-22 20:33:07,782 - INFO - musicbot.bot | In bot.py::MainThread(19360), line 1141 in on_ready: Owner:     743373378672656445/kintama#8473

[17.4471249580383301] 2022-03-22 20:33:07,782 - INFO - musicbot.bot | In bot.py::MainThread(19360), line 1147 in on_ready: Guild List:
[17.4471249580383301] 2022-03-22 20:33:07,782 - INFO - musicbot.bot | In bot.py::MainThread(19360), line 1151 in on_ready:  - META CLUB @theyoungsatoshi
[17.4471249580383301] 2022-03-22 20:33:07,782 - INFO - musicbot.bot | In bot.py::MainThread(19360), line 1151 in on_ready:  - test server 2
[17.4471249580383301] 2022-03-22 20:33:07,782 - INFO - musicbot.bot | In bot.py::MainThread(19360), line 1224 in on_ready: Not bound to any text channels
[17.4627521038055420] 2022-03-22 20:33:07,798 - INFO - musicbot.bot | In bot.py::MainThread(19360), line 1260 in on_ready: Not autojoining any voice channels
[141.9129514694213867] 2022-03-22 20:35:12,248 - INFO - musicbot.bot | In bot.py::MainThread(19360), line 3922 in on_message: 743373378672656445/kintama#8473: !help
[209.8314771652221680] 2022-03-22 20:36:20,167 - ERROR - musicbot.bot | In bot.py::MainThread(19360), line 1084 in run: Error in cleanup
Traceback (most recent call last):
  File "E:\discord bot\music-bot\MusicBot\musicbot\bot.py", line 1070, in run
    self.loop.run_until_complete(self.start(*self.config.auth))
  File "C:\Users\Baig\AppData\Local\Programs\Python\Python39\lib\asyncio\base_events.py", line 629, in run_until_complete
    self.run_forever()
  File "C:\Users\Baig\AppData\Local\Programs\Python\Python39\lib\asyncio\windows_events.py", line 316, in run_forever
    super().run_forever()
  File "C:\Users\Baig\AppData\Local\Programs\Python\Python39\lib\asyncio\base_events.py", line 596, in run_forever
    self._run_once()
  File "C:\Users\Baig\AppData\Local\Programs\Python\Python39\lib\asyncio\base_events.py", line 1854, in _run_once
    event_list = self._selector.select(timeout)
  File "C:\Users\Baig\AppData\Local\Programs\Python\Python39\lib\asyncio\windows_events.py", line 434, in select
    self._poll(timeout)
  File "C:\Users\Baig\AppData\Local\Programs\Python\Python39\lib\asyncio\windows_events.py", line 783, in _poll
    status = _overlapped.GetQueuedCompletionStatus(self._iocp, ms)
KeyboardInterrupt

During handling of the above exception, another exception occurred:

Traceback (most recent call last):
  File "E:\discord bot\music-bot\MusicBot\musicbot\bot.py", line 1082, in run
    self._cleanup()
  File "E:\discord bot\music-bot\MusicBot\musicbot\bot.py", line 1057, in _cleanup
    pending = asyncio.all_tasks()
  File "C:\Users\Baig\AppData\Local\Programs\Python\Python39\lib\asyncio\tasks.py", line 44, in all_tasks
    loop = events.get_running_loop()
RuntimeError: no running event loop
